<?xml version="1.0"?>
<robot name="andrzej" xmlns:xacro="http://www.ros.org/wiki/xacro">

<xacro:macro name="finger_link" params="arm suffix reflect" >
  <link name="arm_${arm}_finger_${suffix}_link">
    <visual>
      <geometry>
        <box size=".01 .005 .08"/>
      </geometry>
      <origin xyz="0 ${reflect*0.025} .0325"/>
      <material name="gray"/>
    </visual>

    <visual>
      <geometry>
        <box size=".02 .025 .04"/>
      </geometry>
      <origin xyz="-0.005 ${reflect*0.01} .045"/>
      <material name="gray"/>
    </visual>

    <xacro:default_inertial mass="${gripper_finger_mass}"/>
  </link>
</xacro:macro>

<xacro:macro name="gripper_joint" params="arm reflect" >
  <joint name="arm_${arm}_gripper_joint" type="revolute">
    <axis xyz="0 1 0"/>
    <limit effort="1000.0" lower="0.0" upper="0.548" velocity="0.5"/>
    <origin rpy="0 0 ${reflect*pi/2-pi/2}" xyz="${reflect*0.015} 0 0"/>
    <parent link="arm_${arm}_gripper_base"/>
    <child link="arm_${arm}_finger_left_link"/>
  </joint>

  <transmission name="arm_${arm}_finger_left_trans">
    <type>transmission_interface/SimpleTransmission</type>
    <joint name="arm_${arm}_gripper_joint">
      <hardwareInterface>hardware_interface/PositionJointInterface</hardwareInterface>
    </joint>
    <actuator name="arm_${arm}_gripper_servo">
      <hardwareInterface>hardware_interface/PositionJointInterface</hardwareInterface>
      <mechanicalReduction>1</mechanicalReduction>
    </actuator>
  </transmission>

  <joint name="arm_${arm}_finger_right_joint" type="revolute">
    <axis xyz="0 1 0"/>
    <limit effort="1000.0" lower="0.0" upper="0.548" velocity="0.5"/>
    <origin rpy="0 0 ${-reflect*pi/2-pi/2}" xyz="${-reflect*0.015} 0 0"/>
    <parent link="arm_${arm}_gripper_base"/>
    <child link="arm_${arm}_finger_right_link"/>
    <mimic joint="arm_${arm}_finger_left_joint" multiplier="1" offset="0"/>
  </joint>
</xacro:macro>

<xacro:macro name="gripper" params="arm" >

  <link name="arm_${arm}_gripper_base">
    <visual>
      <geometry>
        <box size=".045 .04 .02"/>
      </geometry>
      <origin xyz="0 0 .005"/>
      <material name="black"/>
    </visual>

    <xacro:default_inertial mass="${gripper_base_mass}"/>
  </link>

  <joint name="arm_${arm}_gripper_base_joint" type="fixed">
    <parent link="arm_${arm}_link_5"/>
    <child link="arm_${arm}_gripper_base"/>
    <origin rpy="0 0 0" xyz="0 0 0.05"/>
  </joint>

  <xacro:call macro="finger_link" arm="${arm}" suffix="left" reflect="1"/>
  <xacro:call macro="finger_link" arm="${arm}" suffix="right" reflect="-1"/>
  <xacro:call macro="gripper_joint" arm="${arm}" reflect="1"/>

</xacro:macro>

</robot>
